Workbook

Sheet Parts Inventory
A1: PRINTEX ENGINEERS
A2: Parts Inventory & Price List
A3: Transcribed from the handwritten parts register (Columns A-F). Buying prices in USD; selling prices in KES.
A5: Item No. | B5: Register Column | C5: Category | D5: Part Description | E5: Part No. | F5: Qty | G5: Unit | H5: Buying Price (USD) | I5: Selling Price (KES) | J5: Stock Value (USD) | K5: Potential Sales (KES) | L5: Notes
A6: 1 | B6: A | C6: Valves, Cylinders & Pistons | D6: Control Valve | E6: M2.184.1111/05 | F6: 9 | G6: Pcs | H6: 30 | I6: 12400 | J6: =IF(AND(ISNUMBER(F6),ISNUMBER(H6)),F6*H6,"") -> 270 | K6: =IF(AND(ISNUMBER(F6),ISNUMBER(I6)),F6*I6,"") -> 111600
A7: 2 | B7: A | C7: Valves, Cylinders & Pistons | D7: Control Valve | E7: M2.184.1121/05 | F7: 9 | G7: Pcs | H7: 30 | I7: 12400 | J7: =IF(AND(ISNUMBER(F7),ISNUMBER(H7)),F7*H7,"") -> 270 | K7: =IF(AND(ISNUMBER(F7),ISNUMBER(I7)),F7*I7,"") -> 111600
A8: 3 | B8: A | C8: Valves, Cylinders & Pistons | D8: Control Valve | E8: M2.184.1131 | F8: 3 | G8: Pcs | I8: 16250 | J8: =IF(AND(ISNUMBER(F8),ISNUMBER(H8)),F8*H8,"") | K8: =IF(AND(ISNUMBER(F8),ISNUMBER(I8)),F8*I8,"") -> 48750 | L8: Buying price not recorded
A9: 4 | B9: A | C9: Valves, Cylinders & Pistons | D9: Vibrator Valve | E9: G2.184.0060 | F9: 10 | G9: Pcs | H9: 35 | I9: 14800 | J9: =IF(AND(ISNUMBER(F9),ISNUMBER(H9)),F9*H9,"") -> 350 | K9: =IF(AND(ISNUMBER(F9),ISNUMBER(I9)),F9*I9,"") -> 148000
A10: 5 | B10: A | C10: Valves, Cylinders & Pistons | D10: Vibrator Valve | E10: G2.184.0040 | F10: 6 | G10: Pcs | H10: 34 | I10: 15200 | J10: =IF(AND(ISNUMBER(F10),ISNUMBER(H10)),F10*H10,"") -> 204 | K10: =IF(AND(ISNUMBER(F10),ISNUMBER(I10)),F10*I10,"") -> 91200
A11: 6 | B11: A | C11: Valves, Cylinders & Pistons | D11: Vibrator Valve | E11: 61.184.1133 | F11: 6 | G11: Pcs | H11: 35 | I11: 14800 | J11: =IF(AND(ISNUMBER(F11),ISNUMBER(H11)),F11*H11,"") -> 210 | K11: =IF(AND(ISNUMBER(F11),ISNUMBER(I11)),F11*I11,"") -> 88800
A12: 7 | B12: A | C12: Valves, Cylinders & Pistons | D12: Vibrator Valve | E12: 61.184.1131 | F12: 3 | G12: Pcs | H12: 35 | I12: 14800 | J12: =IF(AND(ISNUMBER(F12),ISNUMBER(H12)),F12*H12,"") -> 105 | K12: =IF(AND(ISNUMBER(F12),ISNUMBER(I12)),F12*I12,"") -> 44400
A13: 8 | B13: A | C13: Valves, Cylinders & Pistons | D13: Vibrator Valve | E13: L2.335.051 | F13: 2 | G13: Pcs | H13: 35 | I13: 14800 | J13: =IF(AND(ISNUMBER(F13),ISNUMBER(H13)),F13*H13,"") -> 70 | K13: =IF(AND(ISNUMBER(F13),ISNUMBER(I13)),F13*I13,"") -> 29600
A14: 9 | B14: A | C14: Valves, Cylinders & Pistons | D14: Vibrator Valve | E14: M2.184.1071 | F14: 3 | G14: Pcs | H14: 35 | I14: 15200 | J14: =IF(AND(ISNUMBER(F14),ISNUMBER(H14)),F14*H14,"") -> 105 | K14: =IF(AND(ISNUMBER(F14),ISNUMBER(I14)),F14*I14,"") -> 45600
A15: 10 | B15: A | C15: Valves, Cylinders & Pistons | D15: Vibrator Valve | E15: 61.184.1171 | F15: 3 | G15: Pcs | H15: 35 | I15: 14800 | J15: =IF(AND(ISNUMBER(F15),ISNUMBER(H15)),F15*H15,"") -> 105 | K15: =IF(AND(ISNUMBER(F15),ISNUMBER(I15)),F15*I15,"") -> 44400
A16: 11 | B16: A | C16: Valves, Cylinders & Pistons | D16: Solenoid Valve | E16: 61.184.1311 | F16: 13 | G16: Pcs | H16: 28 | I16: 18130 | J16: =IF(AND(ISNUMBER(F16),ISNUMBER(H16)),F16*H16,"") -> 364 | K16: =IF(AND(ISNUMBER(F16),ISNUMBER(I16)),F16*I16,"") -> 235690
A17: 12 | B17: A | C17: Valves, Cylinders & Pistons | D17: Solenoid Valve | E17: 98.184.1051 | F17: 14 | G17: Pcs | H17: 28 | I17: 18620 | J17: =IF(AND(ISNUMBER(F17),ISNUMBER(H17)),F17*H17,"") -> 392 | K17: =IF(AND(ISNUMBER(F17),ISNUMBER(I17)),F17*I17,"") -> 260680 | L17: Part no. written over a crossed-out entry
A18: 13 | B18: A | C18: Valves, Cylinders & Pistons | D18: Pneumatic Valve | E18: L2.334.002 | F18: 2 | G18: Pcs | J18: =IF(AND(ISNUMBER(F18),ISNUMBER(H18)),F18*H18,"") | K18: =IF(AND(ISNUMBER(F18),ISNUMBER(I18)),F18*I18,"") | L18: No prices recorded
A19: 14 | B19: A | C19: Valves, Cylinders & Pistons | D19: Pneumatic Valve | E19: 87.334.010 | F19: 3 | G19: Pcs | H19: 18 | I19: 18500 | J19: =IF(AND(ISNUMBER(F19),ISNUMBER(H19)),F19*H19,"") -> 54 | K19: =IF(AND(ISNUMBER(F19),ISNUMBER(I19)),F19*I19,"") -> 55500
A20: 15 | B20: A | C20: Valves, Cylinders & Pistons | D20: Pneumatic Valve | E20: 00.580.3909 | F20: 11 | G20: Pcs | H20: 25 | I20: 18250 | J20: =IF(AND(ISNUMBER(F20),ISNUMBER(H20)),F20*H20,"") -> 275 | K20: =IF(AND(ISNUMBER(F20),ISNUMBER(I20)),F20*I20,"") -> 200750
A21: 16 | B21: A | C21: Valves, Cylinders & Pistons | D21: Pneumatic Valve | E21: 00.580.3930 | F21: 2 | G21: Pcs | H21: 18 | J21: =IF(AND(ISNUMBER(F21),ISNUMBER(H21)),F21*H21,"") -> 36 | K21: =IF(AND(ISNUMBER(F21),ISNUMBER(I21)),F21*I21,"") | L21: Selling price not recorded
A22: 17 | B22: A | C22: Valves, Cylinders & Pistons | D22: Pneumatic Cylinder | E22: F4.334.044 | F22: 1 | G22: Pc | H22: 25 | I22: 18250 | J22: =IF(AND(ISNUMBER(F22),ISNUMBER(H22)),F22*H22,"") -> 25 | K22: =IF(AND(ISNUMBER(F22),ISNUMBER(I22)),F22*I22,"") -> 18250
A23: 18 | B23: A | C23: Valves, Cylinders & Pistons | D23: Control Valve | E23: 61.184.1191 | F23: 1 | G23: Pc | J23: =IF(AND(ISNUMBER(F23),ISNUMBER(H23)),F23*H23,"") | K23: =IF(AND(ISNUMBER(F23),ISNUMBER(I23)),F23*I23,"") | L23: No prices recorded
A24: 19 | B24: A | C24: Valves, Cylinders & Pistons | D24: Cylinder Valve | E24: F4.334.036/03 | F24: 1 | G24: Pc | H24: 26 | I24: 14500 | J24: =IF(AND(ISNUMBER(F24),ISNUMBER(H24)),F24*H24,"") -> 26 | K24: =IF(AND(ISNUMBER(F24),ISNUMBER(I24)),F24*I24,"") -> 14500
A25: 20 | B25: A | C25: Valves, Cylinders & Pistons | D25: Solenoid Valve | E25: G4.334.004/03 | F25: 1 | G25: Pc | H25: 26 | I25: 14500 | J25: =IF(AND(ISNUMBER(F25),ISNUMBER(H25)),F25*H25,"") -> 26 | K25: =IF(AND(ISNUMBER(F25),ISNUMBER(I25)),F25*I25,"") -> 14500
A26: 21 | B26: A | C26: Valves, Cylinders & Pistons | D26: Piston | E26: L2.007.531 | F26: 1 | G26: Pc | H26: 210 | I26: 65000 | J26: =IF(AND(ISNUMBER(F26),ISNUMBER(H26)),F26*H26,"") -> 210 | K26: =IF(AND(ISNUMBER(F26),ISNUMBER(I26)),F26*I26,"") -> 65000
A27: 22 | B27: A | C27: Valves, Cylinders & Pistons | D27: Solenoid Valve | E27: 87.334.001/02 | F27: 1 | G27: Pc | J27: =IF(AND(ISNUMBER(F27),ISNUMBER(H27)),F27*H27,"") | K27: =IF(AND(ISNUMBER(F27),ISNUMBER(I27)),F27*I27,"") | L27: No prices recorded
A28: 23 | B28: A | C28: Valves, Cylinders & Pistons | D28: Pneumatic Cylinder | E28: 00.580.4275 | F28: 1 | G28: Pc | H28: 27 | J28: =IF(AND(ISNUMBER(F28),ISNUMBER(H28)),F28*H28,"") -> 27 | K28: =IF(AND(ISNUMBER(F28),ISNUMBER(I28)),F28*I28,"") | L28: Selling price not recorded
A29: 24 | B29: A | C29: Valves, Cylinders & Pistons | D29: Solenoid Valve | E29: F7.335.002 | F29: 1 | G29: Pc | H29: 26 | I29: 14500 | J29: =IF(AND(ISNUMBER(F29),ISNUMBER(H29)),F29*H29,"") -> 26 | K29: =IF(AND(ISNUMBER(F29),ISNUMBER(I29)),F29*I29,"") -> 14500
A30: 25 | B30: A | C30: Valves, Cylinders & Pistons | D30: Solenoid Valve | E30: 00.580.4300/02 | F30: 2 | G30: Pcs | H30: 14 | I30: 14500 | J30: =IF(AND(ISNUMBER(F30),ISNUMBER(H30)),F30*H30,"") -> 28 | K30: =IF(AND(ISNUMBER(F30),ISNUMBER(I30)),F30*I30,"") -> 29000
A31: 26 | B31: A | C31: Valves, Cylinders & Pistons | D31: Pneumatic Valve | E31: 87.334.001 | F31: 4 | G31: Pcs | H31: 25 | I31: 18250 | J31: =IF(AND(ISNUMBER(F31),ISNUMBER(H31)),F31*H31,"") -> 100 | K31: =IF(AND(ISNUMBER(F31),ISNUMBER(I31)),F31*I31,"") -> 73000
A32: 27 | B32: A | C32: Valves, Cylinders & Pistons | D32: Piston | F32: 1 | G32: Pc | H32: 60 | I32: 26800 | J32: =IF(AND(ISNUMBER(F32),ISNUMBER(H32)),F32*H32,"") -> 60 | K32: =IF(AND(ISNUMBER(F32),ISNUMBER(I32)),F32*I32,"") -> 26800 | L32: Part no. not recorded
A33: 28 | B33: B | C33: Bellows, Diaphragms & Spindles | D33: SM52 Bellows | F33: 16 | G33: Pcs | H33: 4.2 | I33: 3000 | J33: =IF(AND(ISNUMBER(F33),ISNUMBER(H33)),F33*H33,"") -> 67.2 | K33: =IF(AND(ISNUMBER(F33),ISNUMBER(I33)),F33*I33,"") -> 48000
A34: 29 | B34: B | C34: Bellows, Diaphragms & Spindles | D34: SM74 Bellows | F34: 20 | G34: Pcs | H34: 4.6 | I34: 4250 | J34: =IF(AND(ISNUMBER(F34),ISNUMBER(H34)),F34*H34,"") -> 92 | K34: =IF(AND(ISNUMBER(F34),ISNUMBER(I34)),F34*I34,"") -> 85000
A35: 30 | B35: B | C35: Bellows, Diaphragms & Spindles | D35: CD74 Bellows | F35: 19 | G35: Pcs | H35: 4.6 | I35: 4950 | J35: =IF(AND(ISNUMBER(F35),ISNUMBER(H35)),F35*H35,"") -> 87.4 | K35: =IF(AND(ISNUMBER(F35),ISNUMBER(I35)),F35*I35,"") -> 94050
A36: 31 | B36: B | C36: Bellows, Diaphragms & Spindles | D36: CD/XL105 Bellows | F36: 4 | G36: Pcs | H36: 4.8 | I36: 6050 | J36: =IF(AND(ISNUMBER(F36),ISNUMBER(H36)),F36*H36,"") -> 19.2 | K36: =IF(AND(ISNUMBER(F36),ISNUMBER(I36)),F36*I36,"") -> 24200
A37: 32 | B37: B | C37: Bellows, Diaphragms & Spindles | D37: PM74 Bellows | F37: 1 | G37: Pc | H37: 2.8 | I37: 3795 | J37: =IF(AND(ISNUMBER(F37),ISNUMBER(H37)),F37*H37,"") -> 2.8 | K37: =IF(AND(ISNUMBER(F37),ISNUMBER(I37)),F37*I37,"") -> 3795
A38: 33 | B38: B | C38: Bellows, Diaphragms & Spindles | D38: SM52 Autoplate Diaphragm | F38: 17 | G38: Pcs | H38: 14 | I38: 9450 | J38: =IF(AND(ISNUMBER(F38),ISNUMBER(H38)),F38*H38,"") -> 238 | K38: =IF(AND(ISNUMBER(F38),ISNUMBER(I38)),F38*I38,"") -> 160650
A39: 34 | B39: B | C39: Bellows, Diaphragms & Spindles | D39: SM/CD102 Autoplate Diaphragm | F39: 9 | G39: Pcs | H39: 14 | I39: 9450 | J39: =IF(AND(ISNUMBER(F39),ISNUMBER(H39)),F39*H39,"") -> 126 | K39: =IF(AND(ISNUMBER(F39),ISNUMBER(I39)),F39*I39,"") -> 85050
A40: 35 | B40: B | C40: Bellows, Diaphragms & Spindles | D40: Technotrans | E40: DS.196.2015 | F40: 9 | G40: Pcs | H40: 11 | I40: 12750 | J40: =IF(AND(ISNUMBER(F40),ISNUMBER(H40)),F40*H40,"") -> 99 | K40: =IF(AND(ISNUMBER(F40),ISNUMBER(I40)),F40*I40,"") -> 114750
A41: 36 | B41: B | C41: Bellows, Diaphragms & Spindles | D41: Friction Wheels | E41: F4.614.5565 | F41: 18 | G41: Pcs | H41: 22 | I41: 6150 | J41: =IF(AND(ISNUMBER(F41),ISNUMBER(H41)),F41*H41,"") -> 396 | K41: =IF(AND(ISNUMBER(F41),ISNUMBER(I41)),F41*I41,"") -> 110700
...

Sheet Summary by Column
A1: Summary by Register Column
A2: All figures calculated live from the 'Parts Inventory' tab.
A4: Column | B4: Category | C4: Line Items | D4: Total Qty | E4: Stock Value (USD) | F4: Potential Sales (KES)
A5: A | B5: Valves, Cylinders & Pistons | C5: =COUNTIFS('Parts Inventory'!$B$6:$B$139,$A5) -> 27 | D5: =SUMIFS('Parts Inventory'!$F$6:$F$139,'Parts Inventory'!$B$6:$B$139,$A5) -> 114 | E5: =SUMIFS('Parts Inventory'!$J$6:$J$139,'Parts Inventory'!$B$6:$B$139,$A5) -> 3338 | F5: =SUMIFS('Parts Inventory'!$K$6:$K$139,'Parts Inventory'!$B$6:$B$139,$A5) -> 1772120
A6: B | B6: Bellows, Diaphragms & Spindles | C6: =COUNTIFS('Parts Inventory'!$B$6:$B$139,$A6) -> 17 | D6: =SUMIFS('Parts Inventory'!$F$6:$F$139,'Parts Inventory'!$B$6:$B$139,$A6) -> 155 | E6: =SUMIFS('Parts Inventory'!$J$6:$J$139,'Parts Inventory'!$B$6:$B$139,$A6) -> 1540.1 | F6: =SUMIFS('Parts Inventory'!$K$6:$K$139,'Parts Inventory'!$B$6:$B$139,$A6) -> 1038245
A7: C | B7: Suckers, Cups & Gears | C7: =COUNTIFS('Parts Inventory'!$B$6:$B$139,$A7) -> 25 | D7: =SUMIFS('Parts Inventory'!$F$6:$F$139,'Parts Inventory'!$B$6:$B$139,$A7) -> 4834 | E7: =SUMIFS('Parts Inventory'!$J$6:$J$139,'Parts Inventory'!$B$6:$B$139,$A7) -> 13281.6 | F7: =SUMIFS('Parts Inventory'!$K$6:$K$139,'Parts Inventory'!$B$6:$B$139,$A7) -> 762010
A8: D | B8: Cam Followers & Bearings | C8: =COUNTIFS('Parts Inventory'!$B$6:$B$139,$A8) -> 18 | D8: =SUMIFS('Parts Inventory'!$F$6:$F$139,'Parts Inventory'!$B$6:$B$139,$A8) -> 83 | E8: =SUMIFS('Parts Inventory'!$J$6:$J$139,'Parts Inventory'!$B$6:$B$139,$A8) -> 2083.5 | F8: =SUMIFS('Parts Inventory'!$K$6:$K$139,'Parts Inventory'!$B$6:$B$139,$A8) -> 824000
A9: E | B9: Grippers, Pins & Blanket Hooks | C9: =COUNTIFS('Parts Inventory'!$B$6:$B$139,$A9) -> 28 | D9: =SUMIFS('Parts Inventory'!$F$6:$F$139,'Parts Inventory'!$B$6:$B$139,$A9) -> 920 | E9: =SUMIFS('Parts Inventory'!$J$6:$J$139,'Parts Inventory'!$B$6:$B$139,$A9) -> 1947 | F9: =SUMIFS('Parts Inventory'!$K$6:$K$139,'Parts Inventory'!$B$6:$B$139,$A9) -> 1632800
A10: F | B10: Springs, Screws & Ink Dividers | C10: =COUNTIFS('Parts Inventory'!$B$6:$B$139,$A10) -> 19 | D10: =SUMIFS('Parts Inventory'!$F$6:$F$139,'Parts Inventory'!$B$6:$B$139,$A10) -> 223 | E10: =SUMIFS('Parts Inventory'!$J$6:$J$139,'Parts Inventory'!$B$6:$B$139,$A10) -> 761.2 | F10: =SUMIFS('Parts Inventory'!$K$6:$K$139,'Parts Inventory'!$B$6:$B$139,$A10) -> 375650
A11: TOTAL | C11: =SUM(C5:C10) -> 134 | D11: =SUM(D5:D10) -> 6329 | E11: =SUM(E5:E10) -> 22951.4 | F11: =SUM(F5:F10) -> 6404825

Sheet Struck-Out Entries
A1: Entries Struck Through in the Register
A2: Kept for audit reference only. These lines are NOT counted as stock.
A4: Register Column | B4: Part Description | C4: Part No. | D4: Qty | E4: Unit | F4: Buying Price (USD) | G4: Selling Price (KES) | H4: Notes
A5: D | B5: Cam Follower | C5: F-229817.01 | E5: Pcs | F5: 30 | G5: 14750 | H5: Struck through in register
A6: E | B6: Delivery Gripper | D6: 100 | E6: Pcs | F6: 3.5 | G6: 2350 | H6: Struck through in register (duplicate of S1404F line)

Sheet Transcription Notes
A1: Transcription Notes & Assumptions
A3: Source | B3: Six photographs of the handwritten Printex Engineers parts register, labelled Column A through Column F.
A4: Currency | B4: Buying prices were written with a $ sign and are recorded as USD. Selling prices were written without a symbol in the thousands (e.g. 12,400.00) and are recorded as KES. Confirm before publishing a price list.
A5: Blank prices | B5: Several lines in the register have no buying price, no selling price, or neither. These cells are left blank rather than filled with zero, so totals reflect priced lines only.
A6: Struck-out lines | B6: Two lines were crossed out in the register. They are held on the 'Struck-Out Entries' tab and excluded from all totals.
A7: Price corrections | B7: Where a price was overwritten in the register, the later value is used and the change is recorded in the Notes column.
A8: Items to verify | B8: Handwriting was unclear on a small number of entries. Each is flagged in the Notes column of the inventory tab. The main ones are listed below.
A10: Tapered Pin 00.540.0081 (Col. E) | B10: Middle three digits are ambiguous - could read 00.500.0081.
A11: Diaphragm Clips CPI (Col. B) | B11: Trailing letters read as 'CPI'.
A12: Friction Wheels CPH (Col. B) | B12: Trailing letters read as 'CPh'.
A13: Worm Gear 42.006.029 (Col. C) | B13: Description read as 'Worm Gear' by comparison with the 'Gear Worm M2.006.001' line at the same buying price.
A14: Feeder Sucker Rod (Col. C) | B14: Buying price USD 10 exceeds the KES 100 selling price as written.
A15: Rubber Sucker 45 x 13 (Col. C) | B15: Buying price written as $10; all comparable suckers are priced at $0.10-$0.30, so this may be $0.10.
... A18: Cross-references | B18: Two margin notes in Column D have been carried into the Notes column: 00.550.1471 against F-217813.04, and F2.011.121 against F-229025.
